Workbook

Sheet Dashboard
B1: TUBULAR MONITORING — DASHBOARD
B2: TOTAL RIGS | D2: TOTAL HOISTS | F2: TOTAL UNITS | H2: TUBULAR TYPES
B3: 28 | D3: 5 | F3: 33 | H3: 40
B5: TUBULAR DESCRIPTION | C5: ON CONTRACT | D5: PREMIUM ●● White | E5: CLASS 2 ● Yellow | F5: CLASS 3 ● Orange | G5: SCRAP ● Red | H5: NEEDS INSPECTION | I5: NET SHORTFALL | J5: STATUS
B6: ◆ DRILL PIPE
B7: 3-1/2" DP, G-105, 13.3 ppf, NC38 | C7: =Master!D35 -> 468 | D7: =Master!E35 -> 779 | E7: =Master!F35 -> 0 | F7: =Master!G35 -> 0 | G7: =Master!H35 -> 0 | H7: =Master!I35 -> 0 | I7: =(D7+E7)-C7 -> 311 | J7: =IF(C7=0,IF(D7+E7=0,"NO DATA","UNCONTRACTED"),IF(I7<0,"⚠ SHORT",IF(I7=0,"✔ MET","✚ SURPLUS"))) -> ✚ SURPLUS
B8: 3-1/2" DP, G-105, 15.5 ppf, NC38 | C8: =Master!J35 -> 338 | D8: =Master!K35 -> 347 | E8: =Master!L35 -> 0 | F8: =Master!M35 -> 0 | G8: =Master!N35 -> 0 | H8: =Master!O35 -> 8 | I8: =(D8+E8)-C8 -> 9 | J8: =IF(C8=0,IF(D8+E8=0,"NO DATA","UNCONTRACTED"),IF(I8<0,"⚠ SHORT",IF(I8=0,"✔ MET","✚ SURPLUS"))) -> ✚ SURPLUS
B9: 4" DP, G-105, 14.0 ppf, HLIST39 | C9: =Master!P35 -> 0 | D9: =Master!Q35 -> 0 | E9: =Master!R35 -> 0 | F9: =Master!S35 -> 0 | G9: =Master!T35 -> 0 | H9: =Master!U35 -> 0 | I9: =(D9+E9)-C9 -> 0 | J9: =IF(C9=0,IF(D9+E9=0,"NO DATA","UNCONTRACTED"),IF(I9<0,"⚠ SHORT",IF(I9=0,"✔ MET","✚ SURPLUS"))) -> NO DATA
B10: 4" DP, G-105, 15.7 ppf, HLIST39 | C10: =Master!V35 -> 534 | D10: =Master!W35 -> 387 | E10: =Master!X35 -> 0 | F10: =Master!Y35 -> 0 | G10: =Master!Z35 -> 6 | H10: =Master!AA35 -> 14 | I10: =(D10+E10)-C10 -> -147 | J10: =IF(C10=0,IF(D10+E10=0,"NO DATA","UNCONTRACTED"),IF(I10<0,"⚠ SHORT",IF(I10=0,"✔ MET","✚ SURPLUS"))) -> ⚠ SHORT
B11: 4" DP, G-105, 14.0 ppf, XT39 | C11: =Master!AB35 -> 728 | D11: =Master!AC35 -> 815 | E11: =Master!AD35 -> 0 | F11: =Master!AE35 -> 0 | G11: =Master!AF35 -> 4 | H11: =Master!AG35 -> 0 | I11: =(D11+E11)-C11 -> 87 | J11: =IF(C11=0,IF(D11+E11=0,"NO DATA","UNCONTRACTED"),IF(I11<0,"⚠ SHORT",IF(I11=0,"✔ MET","✚ SURPLUS"))) -> ✚ SURPLUS
B12: 4" DP, G-105, 15.7 ppf, XT39 | C12: =Master!AH35 -> 2250 | D12: =Master!AI35 -> 1518 | E12: =Master!AJ35 -> 0 | F12: =Master!AK35 -> 0 | G12: =Master!AL35 -> 59 | H12: =Master!AM35 -> 0 | I12: =(D12+E12)-C12 -> -732 | J12: =IF(C12=0,IF(D12+E12=0,"NO DATA","UNCONTRACTED"),IF(I12<0,"⚠ SHORT",IF(I12=0,"✔ MET","✚ SURPLUS"))) -> ⚠ SHORT
B13: 4" DP, G-105, 14.0 ppf, HT40 | C13: =Master!AN35 -> 268 | D13: =Master!AO35 -> 265 | E13: =Master!AP35 -> 0 | F13: =Master!AQ35 -> 0 | G13: =Master!AR35 -> 0 | H13: =Master!AS35 -> 0 | I13: =(D13+E13)-C13 -> -3 | J13: =IF(C13=0,IF(D13+E13=0,"NO DATA","UNCONTRACTED"),IF(I13<0,"⚠ SHORT",IF(I13=0,"✔ MET","✚ SURPLUS"))) -> ⚠ SHORT
B14: 4" DP, G-105, 15.7 ppf, HT40 | C14: =Master!AT35 -> 210 | D14: =Master!AU35 -> 207 | E14: =Master!AV35 -> 0 | F14: =Master!AW35 -> 0 | G14: =Master!AX35 -> 0 | H14: =Master!AY35 -> 0 | I14: =(D14+E14)-C14 -> -3 | J14: =IF(C14=0,IF(D14+E14=0,"NO DATA","UNCONTRACTED"),IF(I14<0,"⚠ SHORT",IF(I14=0,"✔ MET","✚ SURPLUS"))) -> ⚠ SHORT
B15: 4" DP, S-135, 15.7 ppf, XT39 | C15: =Master!AZ35 -> 208 | D15: =Master!BA35 -> 1080 | E15: =Master!BB35 -> 0 | F15: =Master!BC35 -> 0 | G15: =Master!BD35 -> 155 | H15: =Master!BE35 -> 0 | I15: =(D15+E15)-C15 -> 872 | J15: =IF(C15=0,IF(D15+E15=0,"NO DATA","UNCONTRACTED"),IF(I15<0,"⚠ SHORT",IF(I15=0,"✔ MET","✚ SURPLUS"))) -> ✚ SURPLUS
B16: 5" DP, G-105, 19.5 ppf, NC50 | C16: =Master!BF35 -> 3941 | D16: =Master!BG35 -> 2745 | E16: =Master!BH35 -> 0 | F16: =Master!BI35 -> 0 | G16: =Master!BJ35 -> 301 | H16: =Master!BK35 -> 70 | I16: =(D16+E16)-C16 -> -1196 | J16: =IF(C16=0,IF(D16+E16=0,"NO DATA","UNCONTRACTED"),IF(I16<0,"⚠ SHORT",IF(I16=0,"✔ MET","✚ SURPLUS"))) -> ⚠ SHORT
B17: 5" DP, G-105, 25.6 ppf, NC50 | C17: =Master!BL35 -> 522 | D17: =Master!BM35 -> 1126 | E17: =Master!BN35 -> 0 | F17: =Master!BO35 -> 0 | G17: =Master!BP35 -> 45 | H17: =Master!BQ35 -> 28 | I17: =(D17+E17)-C17 -> 604 | J17: =IF(C17=0,IF(D17+E17=0,"NO DATA","UNCONTRACTED"),IF(I17<0,"⚠ SHORT",IF(I17=0,"✔ MET","✚ SURPLUS"))) -> ✚ SURPLUS
B18: 5" DP, S-135, 19.5 ppf, NC50 | C18: =Master!BR35 -> 364 | D18: =Master!BS35 -> 197 | E18: =Master!BT35 -> 0 | F18: =Master!BU35 -> 0 | G18: =Master!BV35 -> 0 | H18: =Master!BW35 -> 0 | I18: =(D18+E18)-C18 -> -167 | J18: =IF(C18=0,IF(D18+E18=0,"NO DATA","UNCONTRACTED"),IF(I18<0,"⚠ SHORT",IF(I18=0,"✔ MET","✚ SURPLUS"))) -> ⚠ SHORT
B19: 5-1/2" DP, G-105, 24.7 ppf, DELTA544 | C19: =Master!BX35 -> 350 | D19: =Master!BY35 -> 411 | E19: =Master!BZ35 -> 0 | F19: =Master!CA35 -> 0 | G19: =Master!CB35 -> 0 | H19: =Master!CC35 -> 0 | I19: =(D19+E19)-C19 -> 61 | J19: =IF(C19=0,IF(D19+E19=0,"NO DATA","UNCONTRACTED"),IF(I19<0,"⚠ SHORT",IF(I19=0,"✔ MET","✚ SURPLUS"))) -> ✚ SURPLUS
B20: ◆ HWDP
B21: 3-1/2" HWDP, NC38, 25.3 ppf | C21: =Master!CD35 -> 0 | D21: =Master!CE35 -> 96 | E21: =Master!CF35 -> 0 | F21: =Master!CG35 -> 0 | G21: =Master!CH35 -> 0 | H21: =Master!CI35 -> 0 | I21: =(D21+E21)-C21 -> 96 | J21: =IF(C21=0,IF(D21+E21=0,"NO DATA","UNCONTRACTED"),IF(I21<0,"⚠ SHORT",IF(I21=0,"✔ MET","✚ SURPLUS"))) -> UNCONTRACTED
B22: 4" HWDP, HT40, R-2 | C22: =Master!CJ35 -> 205 | D22: =Master!CK35 -> 113 | E22: =Master!CL35 -> 0 | F22: =Master!CM35 -> 0 | G22: =Master!CN35 -> 0 | H22: =Master!CO35 -> 25 | I22: =(D22+E22)-C22 -> -92 | J22: =IF(C22=0,IF(D22+E22=0,"NO DATA","UNCONTRACTED"),IF(I22<0,"⚠ SHORT",IF(I22=0,"✔ MET","✚ SURPLUS"))) -> ⚠ SHORT
B23: 4" HWDP, XT39, 30.5 ppf | C23: =Master!CP35 -> 122 | D23: =Master!CQ35 -> 93 | E23: =Master!CR35 -> 0 | F23: =Master!CS35 -> 0 | G23: =Master!CT35 -> 0 | H23: =Master!CU35 -> 0 | I23: =(D23+E23)-C23 -> -29 | J23: =IF(C23=0,IF(D23+E23=0,"NO DATA","UNCONTRACTED"),IF(I23<0,"⚠ SHORT",IF(I23=0,"✔ MET","✚ SURPLUS"))) -> ⚠ SHORT
B24: 5" HWDP, NC50, 49.3 ppf | C24: =Master!CV35 -> 500 | D24: =Master!CW35 -> 224 | E24: =Master!CX35 -> 0 | F24: =Master!CY35 -> 0 | G24: =Master!CZ35 -> 5 | H24: =Master!DA35 -> 0 | I24: =(D24+E24)-C24 -> -276 | J24: =IF(C24=0,IF(D24+E24=0,"NO DATA","UNCONTRACTED"),IF(I24<0,"⚠ SHORT",IF(I24=0,"✔ MET","✚ SURPLUS"))) -> ⚠ SHORT
B25: 5" HWDP, R-2 | C25: =Master!DB35 -> 532 | D25: =Master!DC35 -> 447 | E25: =Master!DD35 -> 0 | F25: =Master!DE35 -> 0 | G25: =Master!DF35 -> 15 | H25: =Master!DG35 -> 30 | I25: =(D25+E25)-C25 -> -85 | J25: =IF(C25=0,IF(D25+E25=0,"NO DATA","UNCONTRACTED"),IF(I25<0,"⚠ SHORT",IF(I25=0,"✔ MET","✚ SURPLUS"))) -> ⚠ SHORT
B26: 5-1/2" HWDP, DELTA544, 56.5 ppf | C26: =Master!DH35 -> 132 | D26: =Master!DI35 -> 60 | E26: =Master!DJ35 -> 0 | F26: =Master!DK35 -> 0 | G26: =Master!DL35 -> 0 | H26: =Master!DM35 -> 0 | I26: =(D26+E26)-C26 -> -72 | J26: =IF(C26=0,IF(D26+E26=0,"NO DATA","UNCONTRACTED"),IF(I26<0,"⚠ SHORT",IF(I26=0,"✔ MET","✚ SURPLUS"))) -> ⚠ SHORT
B27: ◆ DRILL COLLAR
B28: 9-1/2" DC, 7-5/8" REG, 217.2 lb/ft | C28: =Master!DN35 -> 54 | D28: =Master!DO35 -> 62 | E28: =Master!DP35 -> 0 | F28: =Master!DQ35 -> 0 | G28: =Master!DR35 -> 0 | H28: =Master!DS35 -> 0 | I28: =(D28+E28)-C28 -> 8 | J28: =IF(C28=0,IF(D28+E28=0,"NO DATA","UNCONTRACTED"),IF(I28<0,"⚠ SHORT",IF(I28=0,"✔ MET","✚ SURPLUS"))) -> ✚ SURPLUS
B29: 8-1/2" DC, 6-5/8" REG | C29: =Master!DT35 -> 67 | D29: =Master!DU35 -> 45 | E29: =Master!DV35 -> 0 | F29: =Master!DW35 -> 0 | G29: =Master!DX35 -> 0 | H29: =Master!DY35 -> 0 | I29: =(D29+E29)-C29 -> -22 | J29: =IF(C29=0,IF(D29+E29=0,"NO DATA","UNCONTRACTED"),IF(I29<0,"⚠ SHORT",IF(I29=0,"✔ MET","✚ SURPLUS"))) -> ⚠ SHORT
B30: 8-1/4" DC, 6-5/8" REG, 150.3 lb/ft | C30: =Master!DZ35 -> 82 | D30: =Master!EA35 -> 97 | E30: =Master!EB35 -> 0 | F30: =Master!EC35 -> 0 | G30: =Master!ED35 -> 0 | H30: =Master!EE35 -> 0 | I30: =(D30+E30)-C30 -> 15 | J30: =IF(C30=0,IF(D30+E30=0,"NO DATA","UNCONTRACTED"),IF(I30<0,"⚠ SHORT",IF(I30=0,"✔ MET","✚ SURPLUS"))) -> ✚ SURPLUS
B31: 6-3/4" DC, NC50, 101.4 lb/ft | C31: =Master!EF35 -> 324 | D31: =Master!EG35 -> 245 | E31: =Master!EH35 -> 11 | F31: =Master!EI35 -> 0 | G31: =Master!EJ35 -> 0 | H31: =Master!EK35 -> 2 | I31: =(D31+E31)-C31 -> -68 | J31: =IF(C31=0,IF(D31+E31=0,"NO DATA","UNCONTRACTED"),IF(I31<0,"⚠ SHORT",IF(I31=0,"✔ MET","✚ SURPLUS"))) -> ⚠ SHORT
B32: 6-1/2" DC, 4" IF | C32: =Master!EL35 -> 258 | D32: =Master!EM35 -> 127 | E32: =Master!EN35 -> 0 | F32: =Master!EO35 -> 0 | G32: =Master!EP35 -> 3 | H32: =Master!EQ35 -> 0 | I32: =(D32+E32)-C32 -> -131 | J32: =IF(C32=0,IF(D32+E32=0,"NO DATA","UNCONTRACTED"),IF(I32<0,"⚠ SHORT",IF(I32=0,"✔ MET","✚ SURPLUS"))) -> ⚠ SHORT
B33: 6-1/4" DC, 4" IF (NC46) | C33: =Master!ER35 -> 26 | D33: =Master!ES35 -> 38 | E33: =Master!ET35 -> 0 | F33: =Master!EU35 -> 0 | G33: =Master!EV35 -> 0 | H33: =Master!EW35 -> 0 | I33: =(D33+E33)-C33 -> 12 | J33: =IF(C33=0,IF(D33+E33=0,"NO DATA","UNCONTRACTED"),IF(I33<0,"⚠ SHORT",IF(I33=0,"✔ MET","✚ SURPLUS"))) -> ✚ SURPLUS
B34: 6-1/2" DC, 4-1/2" IF (NC50) | C34: =Master!EX35 -> 94 | D34: =Master!EY35 -> 119 | E34: =Master!EZ35 -> 0 | F34: =Master!FA35 -> 0 | G34: =Master!FB35 -> 1 | H34: =Master!FC35 -> 0 | I34: =(D34+E34)-C34 -> 25 | J34: =IF(C34=0,IF(D34+E34=0,"NO DATA","UNCONTRACTED"),IF(I34<0,"⚠ SHORT",IF(I34=0,"✔ MET","✚ SURPLUS"))) -> ✚ SURPLUS
B35: 4-3/4" DC, NC38, 47.3 lb/ft | C35: =Master!FD35 -> 80 | D35: =Master!FE35 -> 82 | E35: =Master!FF35 -> 1 | F35: =Master!FG35 -> 0 | G35: =Master!FH35 -> 0 | H35: =Master!FI35 -> 0 | I35: =(D35+E35)-C35 -> 3 | J35: =IF(C35=0,IF(D35+E35=0,"NO DATA","UNCONTRACTED"),IF(I35<0,"⚠ SHORT",IF(I35=0,"✔ MET","✚ SURPLUS"))) -> ✚ SURPLUS
B36: ◆ PUP JOINT
B37: 3-1/2" PUP, G-105, NC38, 13.3 ppf | C37: =Master!FJ35 -> 319 | D37: =Master!FK35 -> 229 | E37: =Master!FL35 -> 0 | F37: =Master!FM35 -> 0 | G37: =Master!FN35 -> 7 | H37: =Master!FO35 -> 0 | I37: =(D37+E37)-C37 -> -90 | J37: =IF(C37=0,IF(D37+E37=0,"NO DATA","UNCONTRACTED"),IF(I37<0,"⚠ SHORT",IF(I37=0,"✔ MET","✚ SURPLUS"))) -> ⚠ SHORT
B38: 3-1/2" PUP, G-105, NC38, 15.5 ppf | C38: =Master!FP35 -> 4 | D38: =Master!FQ35 -> 2 | E38: =Master!FR35 -> 0 | F38: =Master!FS35 -> 0 | G38: =Master!FT35 -> 0 | H38: =Master!FU35 -> 6 | I38: =(D38+E38)-C38 -> -2 | J38: =IF(C38=0,IF(D38+E38=0,"NO DATA","UNCONTRACTED"),IF(I38<0,"⚠ SHORT",IF(I38=0,"✔ MET","✚ SURPLUS"))) -> ⚠ SHORT
B39: 4" PUP, G-105, HLIST39, 14.0 ppf | C39: =Master!FV35 -> 0 | D39: =Master!FW35 -> 2 | E39: =Master!FX35 -> 0 | F39: =Master!FY35 -> 0 | G39: =Master!FZ35 -> 0 | H39: =Master!GA35 -> 0 | I39: =(D39+E39)-C39 -> 2 | J39: =IF(C39=0,IF(D39+E39=0,"NO DATA","UNCONTRACTED"),IF(I39<0,"⚠ SHORT",IF(I39=0,"✔ MET","✚ SURPLUS"))) -> UNCONTRACTED
B40: 4" PUP, G-105, HLIST39, 15.7 ppf | C40: =Master!GB35 -> 0 | D40: =Master!GC35 -> 1 | E40: =Master!GD35 -> 0 | F40: =Master!GE35 -> 0 | G40: =Master!GF35 -> 0 | H40: =Master!GG35 -> 0 | I40: =(D40+E40)-C40 -> 1 | J40: =IF(C40=0,IF(D40+E40=0,"NO DATA","UNCONTRACTED"),IF(I40<0,"⚠ SHORT",IF(I40=0,"✔ MET","✚ SURPLUS"))) -> UNCONTRACTED
B41: 4" PUP, G-105, XT39, 14.0 ppf | C41: =Master!GH35 -> 0 | D41: =Master!GI35 -> 6 | E41: =Master!GJ35 -> 0 | F41: =Master!GK35 -> 0 | G41: =Master!GL35 -> 0 | H41: =Master!GM35 -> 2 | I41: =(D41+E41)-C41 -> 6 | J41: =IF(C41=0,IF(D41+E41=0,"NO DATA","UNCONTRACTED"),IF(I41<0,"⚠ SHORT",IF(I41=0,"✔ MET","✚ SURPLUS"))) -> UNCONTRACTED
...

Sheet Master
A1: TUBULAR MONITORING — MASTER SHEET
A2: Aggregated from Rig & Hoist sheets via SUMIF | 31-May-2026
A3: RIG / HOIST | B3: DATE OF UPDATE | C3: UNIT | D3: 3-1/2" DP, G-105, 13.3 ppf, NC38 | J3: 3-1/2" DP, G-105, 15.5 ppf, NC38 | P3: 4" DP, G-105, 14.0 ppf, HLIST39 | V3: 4" DP, G-105, 15.7 ppf, HLIST39 | AB3: 4" DP, G-105, 14.0 ppf, XT39 | AH3: 4" DP, G-105, 15.7 ppf, XT39 | AN3: 4" DP, G-105, 14.0 ppf, HT40 | AT3: 4" DP, G-105, 15.7 ppf, HT40 | AZ3: 4" DP, S-135, 15.7 ppf, XT39 | BF3: 5" DP, G-105, 19.5 ppf, NC50 | BL3: 5" DP, G-105, 25.6 ppf, NC50 | BR3: 5" DP, S-135, 19.5 ppf, NC50 | BX3: 5-1/2" DP, G-105, 24.7 ppf, DELTA544 | CD3: 3-1/2" HWDP, NC38, 25.3 ppf | CJ3: 4" HWDP, HT40, R-2 | CP3: 4" HWDP, XT39, 30.5 ppf | CV3: 5" HWDP, NC50, 49.3 ppf | DB3: 5" HWDP, R-2 | DH3: 5-1/2" HWDP, DELTA544, 56.5 ppf | DN3: 9-1/2" DC, 7-5/8" REG, 217.2 lb/ft | DT3: 8-1/2" DC, 6-5/8" REG | DZ3: 8-1/4" DC, 6-5/8" REG, 150.3 lb/ft | EF3: 6-3/4" DC, NC50, 101.4 lb/ft | EL3: 6-1/2" DC, 4" IF | ER3: 6-1/4" DC, 4" IF (NC46) | EX3: 6-1/2" DC, 4-1/2" IF (NC50) | FD3: 4-3/4" DC, NC38, 47.3 lb/ft | FJ3: 3-1/2" PUP, G-105, NC38, 13.3 ppf | FP3: 3-1/2" PUP, G-105, NC38, 15.5 ppf | FV3: 4" PUP, G-105, HLIST39, 14.0 ppf | GB3: 4" PUP, G-105, HLIST39, 15.7 ppf | GH3: 4" PUP, G-105, XT39, 14.0 ppf | GN3: 4" PUP, G-105, XT39, 15.7 ppf | GT3: 4" PUP, G-105, HT40, 14.0 ppf | GZ3: 4" PUP, G-105, HT40, 15.7 ppf | HF3: 4" PUP, S-135, XT39, 15.7 ppf | HL3: 5" PUP, G-105, NC50, 19.5 ppf | HR3: 5" PUP, G-105, NC50, 25.6 ppf | HX3: 5" PUP, S-135, NC50, 19.5 ppf | ID3: 5-1/2" PUP, G-105, DELTA544, 24.7 ppf
D4: CONTRACT | E4: PREMIUM | F4: CLASS 2 | G4: CLASS 3 | H4: SCRAP | I4: NEEDS INSP | J4: CONTRACT | K4: PREMIUM | L4: CLASS 2 | M4: CLASS 3 | N4: SCRAP | O4: NEEDS INSP | P4: CONTRACT | Q4: PREMIUM | R4: CLASS 2 | S4: CLASS 3 | T4: SCRAP | U4: NEEDS INSP | V4: CONTRACT | W4: PREMIUM | X4: CLASS 2 | Y4: CLASS 3 | Z4: SCRAP | AA4: NEEDS INSP | AB4: CONTRACT | AC4: PREMIUM | AD4: CLASS 2 | AE4: CLASS 3 | AF4: SCRAP | AG4: NEEDS INSP | AH4: CONTRACT | AI4: PREMIUM | AJ4: CLASS 2 | AK4: CLASS 3 | AL4: SCRAP | AM4: NEEDS INSP | AN4: CONTRACT | AO4: PREMIUM | AP4: CLASS 2 | AQ4: CLASS 3 | AR4: SCRAP | AS4: NEEDS INSP | AT4: CONTRACT | AU4: PREMIUM | AV4: CLASS 2 | AW4: CLASS 3 | AX4: SCRAP | AY4: NEEDS INSP | AZ4: CONTRACT | BA4: PREMIUM | BB4: CLASS 2 | BC4: CLASS 3 | BD4: SCRAP | BE4: NEEDS INSP | BF4: CONTRACT | BG4: PREMIUM | BH4: CLASS 2 | BI4: CLASS 3 | BJ4: SCRAP | BK4: NEEDS INSP | BL4: CONTRACT | BM4: PREMIUM | BN4: CLASS 2 | BO4: CLASS 3 | BP4: SCRAP | BQ4: NEEDS INSP | BR4: CONTRACT | BS4: PREMIUM | BT4: CLASS 2 | BU4: CLASS 3 | BV4: SCRAP | BW4: NEEDS INSP | BX4: CONTRACT | BY4: PREMIUM | BZ4: CLASS 2 | CA4: CLASS 3 | CB4: SCRAP | CC4: NEEDS INSP | CD4: CONTRACT | CE4: PREMIUM | CF4: CLASS 2 | CG4: CLASS 3 | CH4: SCRAP | CI4: NEEDS INSP | CJ4: CONTRACT | CK4: PREMIUM | CL4: CLASS 2 | CM4: CLASS 3 | CN4: SCRAP | CO4: NEEDS INSP | CP4: CONTRACT | CQ4: PREMIUM | CR4: CLASS 2 | CS4: CLASS 3 | CT4: SCRAP | CU4: NEEDS INSP | CV4: CONTRACT | CW4: PREMIUM | CX4: CLASS 2 | CY4: CLASS 3 | CZ4: SCRAP | DA4: NEEDS INSP | DB4: CONTRACT | DC4: PREMIUM | DD4: CLASS 2 | DE4: CLASS 3 | DF4: SCRAP | DG4: NEEDS INSP | DH4: CONTRACT | DI4: PREMIUM | DJ4: CLASS 2 | DK4: CLASS 3 | DL4: SCRAP | DM4: NEEDS INSP | DN4: CONTRACT | DO4: PREMIUM | DP4: CLASS 2 | DQ4: CLASS 3 | DR4: SCRAP | DS4: NEEDS INSP | DT4: CONTRACT | DU4: PREMIUM | DV4: CLASS 2 | DW4: CLASS 3 | DX4: SCRAP | DY4: NEEDS INSP | DZ4: CONTRACT | EA4: PREMIUM | EB4: CLASS 2 | EC4: CLASS 3 | ED4: SCRAP | EE4: NEEDS INSP | EF4: CONTRACT | EG4: PREMIUM | EH4: CLASS 2 | EI4: CLASS 3 | EJ4: SCRAP | EK4: NEEDS INSP | EL4: CONTRACT | EM4: PREMIUM | EN4: CLASS 2 | EO4: CLASS 3 | EP4: SCRAP | EQ4: NEEDS INSP | ER4: CONTRACT | ES4: PREMIUM | ET4: CLASS 2 | EU4: CLASS 3 | EV4: SCRAP | EW4: NEEDS INSP | EX4: CONTRACT | EY4: PREMIUM | EZ4: CLASS 2 | FA4: CLASS 3 | FB4: SCRAP | FC4: NEEDS INSP | FD4: CONTRACT | FE4: PREMIUM | FF4: CLASS 2 | FG4: CLASS 3 | FH4: SCRAP | FI4: NEEDS INSP | FJ4: CONTRACT | FK4: PREMIUM | FL4: CLASS 2 | FM4: CLASS 3 | FN4: SCRAP | FO4: NEEDS INSP | FP4: CONTRACT | FQ4: PREMIUM | FR4: CLASS 2 | FS4: CLASS 3 | FT4: SCRAP | FU4: NEEDS INSP | FV4: CONTRACT | FW4: PREMIUM | FX4: CLASS 2 | FY4: CLASS 3 | FZ4: SCRAP | GA4: NEEDS INSP | GB4: CONTRACT | GC4: PREMIUM | GD4: CLASS 2 | GE4: CLASS 3 | GF4: SCRAP | GG4: NEEDS INSP | GH4: CONTRACT | GI4: PREMIUM | GJ4: CLASS 2 | GK4: CLASS 3 | GL4: SCRAP | GM4: NEEDS INSP | GN4: CONTRACT | GO4: PREMIUM | GP4: CLASS 2 | GQ4: CLASS 3 | GR4: SCRAP | GS4: NEEDS INSP | GT4: CONTRACT | GU4: PREMIUM | GV4: CLASS 2 | GW4: CLASS 3 | GX4: SCRAP | GY4: NEEDS INSP | GZ4: CONTRACT | HA4: PREMIUM | HB4: CLASS 2 | HC4: CLASS 3 | HD4: SCRAP | HE4: NEEDS INSP | HF4: CONTRACT | HG4: PREMIUM | HH4: CLASS 2 | HI4: CLASS 3 | HJ4: SCRAP | HK4: NEEDS INSP | HL4: CONTRACT | HM4: PREMIUM | HN4: CLASS 2 | HO4: CLASS 3 | HP4: SCRAP | HQ4: NEEDS INSP | HR4: CONTRACT | HS4: PREMIUM | HT4: CLASS 2 | HU4: CLASS 3 | HV4: SCRAP | HW4: NEEDS INSP | HX4: CONTRACT | HY4: PREMIUM | HZ4: CLASS 2 | IA4: CLASS 3 | IB4: SCRAP | IC4: NEEDS INSP | ID4: CONTRACT | IE4: PREMIUM | IF4: CLASS 2 | IG4: CLASS 3 | IH4: SCRAP | II4: NEEDS INSP
A6: Rig 103 | B6: ='Rig 103'!D2 -> 45454 | C6: Joints | D6: =SUMIF('Rig 103'!$B:$B,Lists!$A$2,'Rig 103'!$C:$C) -> 0 | E6: =SUMIF('Rig 103'!$B:$B,Lists!$A$2,'Rig 103'!$E:$E) -> 0 | F6: =SUMIF('Rig 103'!$B:$B,Lists!$A$2,'Rig 103'!$F:$F) -> 0 | G6: =SUMIF('Rig 103'!$B:$B,Lists!$A$2,'Rig 103'!$G:$G) -> 0 | H6: =SUMIF('Rig 103'!$B:$B,Lists!$A$2,'Rig 103'!$H:$H) -> 0 | I6: =SUMIF('Rig 103'!$B:$B,Lists!$A$2,'Rig 103'!$I:$I) -> 0 | J6: =SUMIF('Rig 103'!$B:$B,Lists!$A$3,'Rig 103'!$C:$C) -> 0 | K6: =SUMIF('Rig 103'!$B:$B,Lists!$A$3,'Rig 103'!$E:$E) -> 0 | L6: =SUMIF('Rig 103'!$B:$B,Lists!$A$3,'Rig 103'!$F:$F) -> 0 | M6: =SUMIF('Rig 103'!$B:$B,Lists!$A$3,'Rig 103'!$G:$G) -> 0 | N6: =SUMIF('Rig 103'!$B:$B,Lists!$A$3,'Rig 103'!$H:$H) -> 0 | O6: =SUMIF('Rig 103'!$B:$B,Lists!$A$3,'Rig 103'!$I:$I) -> 0 | P6: =SUMIF('Rig 103'!$B:$B,Lists!$A$4,'Rig 103'!$C:$C) -> 0 | Q6: =SUMIF('Rig 103'!$B:$B,Lists!$A$4,'Rig 103'!$E:$E) -> 0 | R6: =SUMIF('Rig 103'!$B:$B,Lists!$A$4,'Rig 103'!$F:$F) -> 0 | S6: =SUMIF('Rig 103'!$B:$B,Lists!$A$4,'Rig 103'!$G:$G) -> 0 | T6: =SUMIF('Rig 103'!$B:$B,Lists!$A$4,'Rig 103'!$H:$H) -> 0 | U6: =SUMIF('Rig 103'!$B:$B,Lists!$A$4,'Rig 103'!$I:$I) -> 0 | V6: =SUMIF('Rig 103'!$B:$B,Lists!$A$5,'Rig 103'!$C:$C) -> 0 | W6: =SUMIF('Rig 103'!$B:$B,Lists!$A$5,'Rig 103'!$E:$E) -> 0 | X6: =SUMIF('Rig 103'!$B:$B,Lists!$A$5,'Rig 103'!$F:$F) -> 0 | Y6: =SUMIF('Rig 103'!$B:$B,Lists!$A$5,'Rig 103'!$G:$G) -> 0 | Z6: =SUMIF('Rig 103'!$B:$B,Lists!$A$5,'Rig 103'!$H:$H) -> 0 | AA6: =SUMIF('Rig 103'!$B:$B,Lists!$A$5,'Rig 103'!$I:$I) -> 0 | AB6: =SUMIF('Rig 103'!$B:$B,Lists!$A$6,'Rig 103'!$C:$C) -> 0 | AC6: =SUMIF('Rig 103'!$B:$B,Lists!$A$6,'Rig 103'!$E:$E) -> 0 | AD6: =SUMIF('Rig 103'!$B:$B,Lists!$A$6,'Rig 103'!$F:$F) -> 0 | AE6: =SUMIF('Rig 103'!$B:$B,Lists!$A$6,'Rig 103'!$G:$G) -> 0 | AF6: =SUMIF('Rig 103'!$B:$B,Lists!$A$6,'Rig 103'!$H:$H) -> 0 | AG6: =SUMIF('Rig 103'!$B:$B,Lists!$A$6,'Rig 103'!$I:$I) -> 0 | AH6: =SUMIF('Rig 103'!$B:$B,Lists!$A$7,'Rig 103'!$C:$C) -> 324 | AI6: =SUMIF('Rig 103'!$B:$B,Lists!$A$7,'Rig 103'!$E:$E) -> 315 | AJ6: =SUMIF('Rig 103'!$B:$B,Lists!$A$7,'Rig 103'!$F:$F) -> 0 | AK6: =SUMIF('Rig 103'!$B:$B,Lists!$A$7,'Rig 103'!$G:$G) -> 0 | AL6: =SUMIF('Rig 103'!$B:$B,Lists!$A$7,'Rig 103'!$H:$H) -> 0 | AM6: =SUMIF('Rig 103'!$B:$B,Lists!$A$7,'Rig 103'!$I:$I) -> 0 | AN6: =SUMIF('Rig 103'!$B:$B,Lists!$A$8,'Rig 103'!$C:$C) -> 0 | AO6: =SUMIF('Rig 103'!$B:$B,Lists!$A$8,'Rig 103'!$E:$E) -> 0 | AP6: =SUMIF('Rig 103'!$B:$B,Lists!$A$8,'Rig 103'!$F:$F) -> 0 | AQ6: =SUMIF('Rig 103'!$B:$B,Lists!$A$8,'Rig 103'!$G:$G) -> 0 | AR6: =SUMIF('Rig 103'!$B:$B,Lists!$A$8,'Rig 103'!$H:$H) -> 0 | AS6: =SUMIF('Rig 103'!$B:$B,Lists!$A$8,'Rig 103'!$I:$I) -> 0 | AT6: =SUMIF('Rig 103'!$B:$B,Lists!$A$9,'Rig 103'!$C:$C) -> 0 | AU6: =SUMIF('Rig 103'!$B:$B,Lists!$A$9,'Rig 103'!$E:$E) -> 0 | AV6: =SUMIF('Rig 103'!$B:$B,Lists!$A$9,'Rig 103'!$F:$F) -> 0 | AW6: =SUMIF('Rig 103'!$B:$B,Lists!$A$9,'Rig 103'!$G:$G) -> 0 | AX6: =SUMIF('Rig 103'!$B:$B,Lists!$A$9,'Rig 103'!$H:$H) -> 0 | AY6: =SUMIF('Rig 103'!$B:$B,Lists!$A$9,'Rig 103'!$I:$I) -> 0 | AZ6: =SUMIF('Rig 103'!$B:$B,Lists!$A$10,'Rig 103'!$C:$C) -> 0 | BA6: =SUMIF('Rig 103'!$B:$B,Lists!$A$10,'Rig 103'!$E:$E) -> 0 | BB6: =SUMIF('Rig 103'!$B:$B,Lists!$A$10,'Rig 103'!$F:$F) -> 0 | BC6: =SUMIF('Rig 103'!$B:$B,Lists!$A$10,'Rig 103'!$G:$G) -> 0 | BD6: =SUMIF('Rig 103'!$B:$B,Lists!$A$10,'Rig 103'!$H:$H) -> 0 | BE6: =SUMIF('Rig 103'!$B:$B,Lists!$A$10,'Rig 103'!$I:$I) -> 0 | BF6: =SUMIF('Rig 103'!$B:$B,Lists!$A$11,'Rig 103'!$C:$C) -> 324 | BG6: =SUMIF('Rig 103'!$B:$B,Lists!$A$11,'Rig 103'!$E:$E) -> 0 | BH6: =SUMIF('Rig 103'!$B:$B,Lists!$A$11,'Rig 103'!$F:$F) -> 0 | BI6: =SUMIF('Rig 103'!$B:$B,Lists!$A$11,'Rig 103'!$G:$G) -> 0 | BJ6: =SUMIF('Rig 103'!$B:$B,Lists!$A$11,'Rig 103'!$H:$H) -> 0 | BK6: =SUMIF('Rig 103'!$B:$B,Lists!$A$11,'Rig 103'!$I:$I) -> 0 | BL6: =SUMIF('Rig 103'!$B:$B,Lists!$A$12,'Rig 103'!$C:$C) -> 0 | BM6: =SUMIF('Rig 103'!$B:$B,Lists!$A$12,'Rig 103'!$E:$E) -> 0 | BN6: =SUMIF('Rig 103'!$B:$B,Lists!$A$12,'Rig 103'!$F:$F) -> 0 | BO6: =SUMIF('Rig 103'!$B:$B,Lists!$A$12,'Rig 103'!$G:$G) -> 0 | BP6: =SUMIF('Rig 103'!$B:$B,Lists!$A$12,'Rig 103'!$H:$H) -> 0 | BQ6: =SUMIF('Rig 103'!$B:$B,Lists!$A$12,'Rig 103'!$I:$I) -> 0 | BR6: =SUMIF('Rig 103'!$B:$B,Lists!$A$13,'Rig 103'!$C:$C) -> 0 | BS6: =SUMIF('Rig 103'!$B:$B,Lists!$A$13,'Rig 103'!$E:$E) -> 0 | BT6: =SUMIF('Rig 103'!$B:$B,Lists!$A$13,'Rig 103'!$F:$F) -> 0 | BU6: =SUMIF('Rig 103'!$B:$B,Lists!$A$13,'Rig 103'!$G:$G) -> 0 | BV6: =SUMIF('Rig 103'!$B:$B,Lists!$A$13,'Rig 103'!$H:$H) -> 0 | BW6: =SUMIF('Rig 103'!$B:$B,Lists!$A$13,'Rig 103'!$I:$I) -> 0 | BX6: =SUMIF('Rig 103'!$B:$B,Lists!$A$14,'Rig 103'!$C:$C) -> 0 | BY6: =SUMIF('Rig 103'!$B:$B,Lists!$A$14,'Rig 103'!$E:$E) -> 0 | BZ6: =SUMIF('Rig 103'!$B:$B,Lists!$A$14,'Rig 103'!$F:$F) -> 0 | CA6: =SUMIF('Rig 103'!$B:$B,Lists!$A$14,'Rig 103'!$G:$G) -> 0 | CB6: =SUMIF('Rig 103'!$B:$B,Lists!$A$14,'Rig 103'!$H:$H) -> 0 | CC6: =SUMIF('Rig 103'!$B:$B,Lists!$A$14,'Rig 103'!$I:$I) -> 0 | CD6: =SUMIF('Rig 103'!$B:$B,Lists!$A$15,'Rig 103'!$C:$C) -> 0 | CE6: =SUMIF('Rig 103'!$B:$B,Lists!$A$15,'Rig 103'!$E:$E) -> 0 | CF6: =SUMIF('Rig 103'!$B:$B,Lists!$A$15,'Rig 103'!$F:$F) -> 0 | CG6: =SUMIF('Rig 103'!$B:$B,Lists!$A$15,'Rig 103'!$G:$G) -> 0 | CH6: =SUMIF('Rig 103'!$B:$B,Lists!$A$15,'Rig 103'!$H:$H) -> 0 | CI6: =SUMIF('Rig 103'!$B:$B,Lists!$A$15,'Rig 103'!$I:$I) -> 0 | CJ6: =SUMIF('Rig 103'!$B:$B,Lists!$A$16,'Rig 103'!$C:$C) -> 0 | CK6: =SUMIF('Rig 103'!$B:$B,Lists!$A$16,'Rig 103'!$E:$E) -> 0 | CL6: =SUMIF('Rig 103'!$B:$B,Lists!$A$16,'Rig 103'!$F:$F) -> 0 | CM6: =SUMIF('Rig 103'!$B:$B,Lists!$A$16,'Rig 103'!$G:$G) -> 0 | CN6: =SUMIF('Rig 103'!$B:$B,Lists!$A$16,'Rig 103'!$H:$H) -> 0 | CO6: =SUMIF('Rig 103'!$B:$B,Lists!$A$16,'Rig 103'!$I:$I) -> 0 | CP6: =SUMIF('Rig 103'!$B:$B,Lists!$A$17,'Rig 103'!$C:$C) -> 0 | CQ6: =SUMIF('Rig 103'!$B:$B,Lists!$A$17,'Rig 103'!$E:$E) -> 0 | CR6: =SUMIF('Rig 103'!$B:$B,Lists!$A$17,'Rig 103'!$F:$F) -> 0 | CS6: =SUMIF('Rig 103'!$B:$B,Lists!$A$17,'Rig 103'!$G:$G) -> 0 | CT6: =SUMIF('Rig 103'!$B:$B,Lists!$A$17,'Rig 103'!$H:$H) -> 0 | CU6: =SUMIF('Rig 103'!$B:$B,Lists!$A$17,'Rig 103'!$I:$I) -> 0 | CV6: =SUMIF('Rig 103'!$B:$B,Lists!$A$18,'Rig 103'!$C:$C) -> 43 | CW6: =SUMIF('Rig 103'!$B:$B,Lists!$A$18,'Rig 103'!$E:$E) -> 10 | CX6: =SUMIF('Rig 103'!$B:$B,Lists!$A$18,'Rig 103'!$F:$F) -> 0 | CY6: =SUMIF('Rig 103'!$B:$B,Lists!$A$18,'Rig 103'!$G:$G) -> 0 | CZ6: =SUMIF('Rig 103'!$B:$B,Lists!$A$18,'Rig 103'!$H:$H) -> 0 | DA6: =SUMIF('Rig 103'!$B:$B,Lists!$A$18,'Rig 103'!$I:$I) -> 0 | DB6: =SUMIF('Rig 103'!$B:$B,Lists!$A$19,'Rig 103'!$C:$C) -> 43 | DC6: =SUMIF('Rig 103'!$B:$B,Lists!$A$19,'Rig 103'!$E:$E) -> 0 | DD6: =SUMIF('Rig 103'!$B:$B,Lists!$A$19,'Rig 103'!$F:$F) -> 0 | DE6: =SUMIF('Rig 103'!$B:$B,Lists!$A$19,'Rig 103'!$G:$G) -> 0 | DF6: =SUMIF('Rig 103'!$B:$B,Lists!$A$19,'Rig 103'!$H:$H) -> 0 | DG6: =SUMIF('Rig 103'!$B:$B,Lists!$A$19,'Rig 103'!$I:$I) -> 0 | DH6: =SUMIF('Rig 103'!$B:$B,Lists!$A$20,'Rig 103'!$C:$C) -> 0 | DI6: =SUMIF('Rig 103'!$B:$B,Lists!$A$20,'Rig 103'!$E:$E) -> 0 | DJ6: =SUMIF('Rig 103'!$B:$B,Lists!$A$20,'Rig 103'!$F:$F) -> 0 | DK6: =SUMIF('Rig 103'!$B:$B,Lists!$A$20,'Rig 103'!$G:$G) -> 0 | DL6: =SUMIF('Rig 103'!$B:$B,Lists!$A$20,'Rig 103'!$H:$H) -> 0 | DM6: =SUMIF('Rig 103'!$B:$B,Lists!$A$20,'Rig 103'!$I:$I) -> 0 | DN6: =SUMIF('Rig 103'!$B:$B,Lists!$A$21,'Rig 103'!$C:$C) -> 0 | DO6: =SUMIF('Rig 103'!$B:$B,Lists!$A$21,'Rig 103'!$E:$E) -> 0 | DP6: =SUMIF('Rig 103'!$B:$B,Lists!$A$21,'Rig 103'!$F:$F) -> 0 | DQ6: =SUMIF('Rig 103'!$B:$B,Lists!$A$21,'Rig 103'!$G:$G) -> 0 | DR6: =SUMIF('Rig 103'!$B:$B,Lists!$A$21,'Rig 103'!$H:$H) -> 0 | DS6: =SUMIF('Rig 103'!$B:$B,Lists!$A$21,'Rig 103'!$I:$I) -> 0 | DT6: =SUMIF('Rig 103'!$B:$B,Lists!$A$22,'Rig 103'!$C:$C) -> 0 | DU6: =SUMIF('Rig 103'!$B:$B,Lists!$A$22,'Rig 103'!$E:$E) -> 3 | DV6: =SUMIF('Rig 103'!$B:$B,Lists!$A$22,'Rig 103'!$F:$F) -> 0 | DW6: =SUMIF('Rig 103'!$B:$B,Lists!$A$22,'Rig 103'!$G:$G) -> 0 | DX6: =SUMIF('Rig 103'!$B:$B,Lists!$A$22,'Rig 103'!$H:$H) -> 0 | DY6: =SUMIF('Rig 103'!$B:$B,Lists!$A$22,'Rig 103'!$I:$I) -> 0 | DZ6: =SUMIF('Rig 103'!$B:$B,Lists!$A$23,'Rig 103'!$C:$C) -> 30 | EA6: =SUMIF('Rig 103'!$B:$B,Lists!$A$23,'Rig 103'!$E:$E) -> 15 | EB6: =SUMIF('Rig 103'!$B:$B,Lists!$A$23,'Rig 103'!$F:$F) -> 0 | EC6: =SUMIF('Rig 103'!$B:$B,Lists!$A$23,'Rig 103'!$G:$G) -> 0 | ED6: =SUMIF('Rig 103'!$B:$B,Lists!$A$23,'Rig 103'!$H:$H) -> 0 | EE6: =SUMIF('Rig 103'!$B:$B,Lists!$A$23,'Rig 103'!$I:$I) -> 0 | EF6: =SUMIF('Rig 103'!$B:$B,Lists!$A$24,'Rig 103'!$C:$C) -> 0 | EG6: =SUMIF('Rig 103'!$B:$B,Lists!$A$24,'Rig 103'!$E:$E) -> 0 | EH6: =SUMIF('Rig 103'!$B:$B,Lists!$A$24,'Rig 103'!$F:$F) -> 0 | EI6: =SUMIF('Rig 103'!$B:$B,Lists!$A$24,'Rig 103'!$G:$G) -> 0 | EJ6: =SUMIF('Rig 103'!$B:$B,Lists!$A$24,'Rig 103'!$H:$H) -> 0 | EK6: =SUMIF('Rig 103'!$B:$B,Lists!$A$24,'Rig 103'!$I:$I) -> 0 | EL6: =SUMIF('Rig 103'!$B:$B,Lists!$A$25,'Rig 103'!$C:$C) -> 30 | EM6: =SUMIF('Rig 103'!$B:$B,Lists!$A$25,'Rig 103'!$E:$E) -> 0 | EN6: =SUMIF('Rig 103'!$B:$B,Lists!$A$25,'Rig 103'!$F:$F) -> 0 | EO6: =SUMIF('Rig 103'!$B:$B,Lists!$A$25,'Rig 103'!$G:$G) -> 0 | EP6: =SUMIF('Rig 103'!$B:$B,Lists!$A$25,'Rig 103'!$H:$H) -> 0 | EQ6: =SUMIF('Rig 103'!$B:$B,Lists!$A$25,'Rig 103'!$I:$I) -> 0 | ER6: =SUMIF('Rig 103'!$B:$B,Lists!$A$26,'Rig 103'!$C:$C) -> 0 | ES6: =SUMIF('Rig 103'!$B:$B,Lists!$A$26,'Rig 103'!$E:$E) -> 11 | ET6: =SUMIF('Rig 103'!$B:$B,Lists!$A$26,'Rig 103'!$F:$F) -> 0 | EU6: =SUMIF('Rig 103'!$B:$B,Lists!$A$26,'Rig 103'!$G:$G) -> 0 | EV6: =SUMIF('Rig 103'!$B:$B,Lists!$A$26,'Rig 103'!$H:$H) -> 0 | EW6: =SUMIF('Rig 103'!$B:$B,Lists!$A$26,'Rig 103'!$I:$I) -> 0 | EX6: =SUMIF('Rig 103'!$B:$B,Lists!$A$27,'Rig 103'!$C:$C) -> 0 | EY6: =SUMIF('Rig 103'!$B:$B,Lists!$A$27,'Rig 103'!$E:$E) -> 7 | EZ6: =SUMIF('Rig 103'!$B:$B,Lists!$A$27,'Rig 103'!$F:$F) -> 0 | FA6: =SUMIF('Rig 103'!$B:$B,Lists!$A$27,'Rig 103'!$G:$G) -> 0 | FB6: =SUMIF('Rig 103'!$B:$B,Lists!$A$27,'Rig 103'!$H:$H) -> 0 | FC6: =SUMIF('Rig 103'!$B:$B,Lists!$A$27,'Rig 103'!$I:$I) -> 0 | FD6: =SUMIF('Rig 103'!$B:$B,Lists!$A$28,'Rig 103'!$C:$C) -> 0 | FE6: =SUMIF('Rig 103'!$B:$B,Lists!$A$28,'Rig 103'!$E:$E) -> 0 | FF6: =SUMIF('Rig 103'!$B:$B,Lists!$A$28,'Rig 103'!$F:$F) -> 0 | FG6: =SUMIF('Rig 103'!$B:$B,Lists!$A$28,'Rig 103'!$G:$G) -> 0 | FH6: =SUMIF('Rig 103'!$B:$B,Lists!$A$28,'Rig 103'!$H:$H) -> 0 | FI6: =SUMIF('Rig 103'!$B:$B,Lists!$A$28,'Rig 103'!$I:$I) -> 0 | FJ6: =SUMIF('Rig 103'!$B:$B,Lists!$A$29,'Rig 103'!$C:$C) -> 20 | FK6: =SUMIF('Rig 103'!$B:$B,Lists!$A$29,'Rig 103'!$E:$E) -> 18 | FL6: =SUMIF('Rig 103'!$B:$B,Lists!$A$29,'Rig 103'!$F:$F) -> 0 | FM6: =SUMIF('Rig 103'!$B:$B,Lists!$A$29,'Rig 103'!$G:$G) -> 0 | FN6: =SUMIF('Rig 103'!$B:$B,Lists!$A$29,'Rig 103'!$H:$H) -> 0 | FO6: =SUMIF('Rig 103'!$B:$B,Lists!$A$29,'Rig 103'!$I:$I) -> 0 | FP6: =SUMIF('Rig 103'!$B:$B,Lists!$A$30,'Rig 103'!$C:$C) -> 0 | FQ6: =SUMIF('Rig 103'!$B:$B,Lists!$A$30,'Rig 103'!$E:$E) -> 0 | FR6: =SUMIF('Rig 103'!$B:$B,Lists!$A$30,'Rig 103'!$F:$F) -> 0 | FS6: =SUMIF('Rig 103'!$B:$B,Lists!$A$30,'Rig 103'!$G:$G) -> 0 | FT6: =SUMIF('Rig 103'!$B:$B,Lists!$A$30,'Rig 103'!$H:$H) -> 0 | FU6: =SUMIF('Rig 103'!$B:$B,Lists!$A$30,'Rig 103'!$I:$I) -> 0 | FV6: =SUMIF('Rig 103'!$B:$B,Lists!$A$31,'Rig 103'!$C:$C) -> 0 | FW6: =SUMIF('Rig 103'!$B:$B,Lists!$A$31,'Rig 103'!$E:$E) -> 0 | FX6: =SUMIF('Rig 103'!$B:$B,Lists!$A$31,'Rig 103'!$F:$F) -> 0 | FY6: =SUMIF('Rig 103'!$B:$B,Lists!$A$31,'Rig 103'!$G:$G) -> 0 | FZ6: =SUMIF('Rig 103'!$B:$B,Lists!$A$31,'Rig 103'!$H:$H) -> 0 | GA6: =SUMIF('Rig 103'!$B:$B,Lists!$A$31,'Rig 103'!$I:$I) -> 0 | GB6: =SUMIF('Rig 103'!$B:$B,Lists!$A$32,'Rig 103'!$C:$C) -> 0 | GC6: =SUMIF('Rig 103'!$B:$B,Lists!$A$32,'Rig 103'!$E:$E) -> 0 | GD6: =SUMIF('Rig 103'!$B:$B,Lists!$A$32,'Rig 103'!$F:$F) -> 0 | GE6: =SUMIF('Rig 103'!$B:$B,Lists!$A$32,'Rig 103'!$G:$G) -> 0 | GF6: =SUMIF('Rig 103'!$B:$B,Lists!$A$32,'Rig 103'!$H:$H) -> 0 | GG6: =SUMIF('Rig 103'!$B:$B,Lists!$A$32,'Rig 103'!$I:$I) -> 0 | GH6: =SUMIF('Rig 103'!$B:$B,Lists!$A$33,'Rig 103'!$C:$C) -> 0 | GI6: =SUMIF('Rig 103'!$B:$B,Lists!$A$33,'Rig 103'!$E:$E) -> 0 | GJ6: =SUMIF('Rig 103'!$B:$B,Lists!$A$33,'Rig 103'!$F:$F) -> 0 | GK6: =SUMIF('Rig 103'!$B:$B,Lists!$A$33,'Rig 103'!$G:$G) -> 0 | GL6: =SUMIF('Rig 103'!$B:$B,Lists!$A$33,'Rig 103'!$H:$H) -> 0 | GM6: =SUMIF('Rig 103'!$B:$B,Lists!$A$33,'Rig 103'!$I:$I) -> 0 | GN6: =SUMIF('Rig 103'!$B:$B,Lists!$A$34,'Rig 103'!$C:$C) -> 0 | GO6: =SUMIF('Rig 103'!$B:$B,Lists!$A$34,'Rig 103'!$E:$E) -> 0 | GP6: =SUMIF('Rig 103'!$B:$B,Lists!$A$34,'Rig 103'!$F:$F) -> 0 | GQ6: =SUMIF('Rig 103'!$B:$B,Lists!$A$34,'Rig 103'!$G:$G) -> 0 | GR6: =SUMIF('Rig 103'!$B:$B,Lists!$A$34,'Rig 103'!$H:$H) -> 0 | GS6: =SUMIF('Rig 103'!$B:$B,Lists!$A$34,'Rig 103'!$I:$I) -> 0 | GT6: =SUMIF('Rig 103'!$B:$B,Lists!$A$35,'Rig 103'!$C:$C) -> 0 | GU6: =SUMIF('Rig 103'!$B:$B,Lists!$A$35,'Rig 103'!$E:$E) -> 0 | GV6: =SUMIF('Rig 103'!$B:$B,Lists!$A$35,'Rig 103'!$F:$F) -> 0 | GW6: =SUMIF('Rig 103'!$B:$B,Lists!$A$35,'Rig 103'!$G:$G) -> 0 | GX6: =SUMIF('Rig 103'!$B:$B,Lists!$A$35,'Rig 103'!$H:$H) -> 0 | GY6: =SUMIF('Rig 103'!$B:$B,Lists!$A$35,'Rig 103'!$I:$I) -> 0 | GZ6: =SUMIF('Rig 103'!$B:$B,Lists!$A$36,'Rig 103'!$C:$C) -> 0 | HA6: =SUMIF('Rig 103'!$B:$B,Lists!$A$36,'Rig 103'!$E:$E) -> 0 | HB6: =SUMIF('Rig 103'!$B:$B,Lists!$A$36,'Rig 103'!$F:$F) -> 0 | HC6: =SUMIF('Rig 103'!$B:$B,Lists!$A$36,'Rig 103'!$G:$G) -> 0 | HD6: =SUMIF('Rig 103'!$B:$B,Lists!$A$36,'Rig 103'!$H:$H) -> 0 | HE6: =SUMIF('Rig 103'!$B:$B,Lists!$A$36,'Rig 103'!$I:$I) -> 0 | HF6: =SUMIF('Rig 103'!$B:$B,Lists!$A$37,'Rig 103'!$C:$C) -> 0 | HG6: =SUMIF('Rig 103'!$B:$B,Lists!$A$37,'Rig 103'!$E:$E) -> 0 | HH6: =SUMIF('Rig 103'!$B:$B,Lists!$A$37,'Rig 103'!$F:$F) -> 0 | HI6: =SUMIF('Rig 103'!$B:$B,Lists!$A$37,'Rig 103'!$G:$G) -> 0 | HJ6: =SUMIF('Rig 103'!$B:$B,Lists!$A$37,'Rig 103'!$H:$H) -> 0 | HK6: =SUMIF('Rig 103'!$B:$B,Lists!$A$37,'Rig 103'!$I:$I) -> 0 | HL6: =SUMIF('Rig 103'!$B:$B,Lists!$A$38,'Rig 103'!$C:$C) -> 0 | HM6: =SUMIF('Rig 103'!$B:$B,Lists!$A$38,'Rig 103'!$E:$E) -> 0 | HN6: =SUMIF('Rig 103'!$B:$B,Lists!$A$38,'Rig 103'!$F:$F) -> 0 | HO6: =SUMIF('Rig 103'!$B:$B,Lists!$A$38,'Rig 103'!$G:$G) -> 0 | HP6: =SUMIF('Rig 103'!$B:$B,Lists!$A$38,'Rig 103'!$H:$H) -> 0 | HQ6: =SUMIF('Rig 103'!$B:$B,Lists!$A$38,'Rig 103'!$I:$I) -> 0 | HR6: =SUMIF('Rig 103'!$B:$B,Lists!$A$39,'Rig 103'!$C:$C) -> 6 | HS6: =SUMIF('Rig 103'!$B:$B,Lists!$A$39,'Rig 103'!$E:$E) -> 0 | HT6: =SUMIF('Rig 103'!$B:$B,Lists!$A$39,'Rig 103'!$F:$F) -> 0 | HU6: =SUMIF('Rig 103'!$B:$B,Lists!$A$39,'Rig 103'!$G:$G) -> 0 | HV6: =SUMIF('Rig 103'!$B:$B,Lists!$A$39,'Rig 103'!$H:$H) -> 0 | HW6: =SUMIF('Rig 103'!$B:$B,Lists!$A$39,'Rig 103'!$I:$I) -> 0 | HX6: =SUMIF('Rig 103'!$B:$B,Lists!$A$40,'Rig 103'!$C:$C) -> 0 | HY6: =SUMIF('Rig 103'!$B:$B,Lists!$A$40,'Rig 103'!$E:$E) -> 0 | HZ6: =SUMIF('Rig 103'!$B:$B,Lists!$A$40,'Rig 103'!$F:$F) -> 0 | IA6: =SUMIF('Rig 103'!$B:$B,Lists!$A$40,'Rig 103'!$G:$G) -> 0 | IB6: =SUMIF('Rig 103'!$B:$B,Lists!$A$40,'Rig 103'!$H:$H) -> 0 | IC6: =SUMIF('Rig 103'!$B:$B,Lists!$A$40,'Rig 103'!$I:$I) -> 0 | ID6: =SUMIF('Rig 103'!$B:$B,Lists!$A$41,'Rig 103'!$C:$C) -> 0 | IE6: =SUMIF('Rig 103'!$B:$B,Lists!$A$41,'Rig 103'!$E:$E) -> 0 | IF6: =SUMIF('Rig 103'!$B:$B,Lists!$A$41,'Rig 103'!$F:$F) -> 0 | IG6: =SUMIF('Rig 103'!$B:$B,Lists!$A$41,'Rig 103'!$G:$G) -> 0 | IH6: =SUMIF('Rig 103'!$B:$B,Lists!$A$41,'Rig 103'!$H:$H) -> 0 | II6: =SUMIF('Rig 103'!$B:$B,Lists!$A$41,'Rig 103'!$I:$I) -> 0
A7: Rig 104 | B7: ='Rig 104'!D2 -> 46173 | C7: Joints | D7: =SUMIF('Rig 104'!$B:$B,Lists!$A$2,'Rig 104'!$C:$C) -> 0 | E7: =SUMIF('Rig 104'!$B:$B,Lists!$A$2,'Rig 104'!$E:$E) -> 0 | F7: =SUMIF('Rig 104'!$B:$B,Lists!$A$2,'Rig 104'!$F:$F) -> 0 | G7: =SUMIF('Rig 104'!$B:$B,Lists!$A$2,'Rig 104'!$G:$G) -> 0 | H7: =SUMIF('Rig 104'!$B:$B,Lists!$A$2,'Rig 104'!$H:$H) -> 0 | I7: =SUMIF('Rig 104'!$B:$B,Lists!$A$2,'Rig 104'!$I:$I) -> 0 | J7: =SUMIF('Rig 104'!$B:$B,Lists!$A$3,'Rig 104'!$C:$C) -> 0 | K7: =SUMIF('Rig 104'!$B:$B,Lists!$A$3,'Rig 104'!$E:$E) -> 0 | L7: =SUMIF('Rig 104'!$B:$B,Lists!$A$3,'Rig 104'!$F:$F) -> 0 | M7: =SUMIF('Rig 104'!$B:$B,Lists!$A$3,'Rig 104'!$G:$G) -> 0 | N7: =SUMIF('Rig 104'!$B:$B,Lists!$A$3,'Rig 104'!$H:$H) -> 0 | O7: =SUMIF('Rig 104'!$B:$B,Lists!$A$3,'Rig 104'!$I:$I) -> 0 | P7: =SUMIF('Rig 104'!$B:$B,Lists!$A$4,'Rig 104'!$C:$C) -> 0 | Q7: =SUMIF('Rig 104'!$B:$B,Lists!$A$4,'Rig 104'!$E:$E) -> 0 | R7: =SUMIF('Rig 104'!$B:$B,Lists!$A$4,'Rig 104'!$F:$F) -> 0 | S7: =SUMIF('Rig 104'!$B:$B,Lists!$A$4,'Rig 104'!$G:$G) -> 0 | T7: =SUMIF('Rig 104'!$B:$B,Lists!$A$4,'Rig 104'!$H:$H) -> 0 | U7: =SUMIF('Rig 104'!$B:$B,Lists!$A$4,'Rig 104'!$I:$I) -> 0 | V7: =SUMIF('Rig 104'!$B:$B,Lists!$A$5,'Rig 104'!$C:$C) -> 324 | W7: =SUMIF('Rig 104'!$B:$B,Lists!$A$5,'Rig 104'!$E:$E) -> 0 | X7: =SUMIF('Rig 104'!$B:$B,Lists!$A$5,'Rig 104'!$F:$F) -> 0 | Y7: =SUMIF('Rig 104'!$B:$B,Lists!$A$5,'Rig 104'!$G:$G) -> 0 | Z7: =SUMIF('Rig 104'!$B:$B,Lists!$A$5,'Rig 104'!$H:$H) -> 0 | AA7: =SUMIF('Rig 104'!$B:$B,Lists!$A$5,'Rig 104'!$I:$I) -> 0 | AB7: =SUMIF('Rig 104'!$B:$B,Lists!$A$6,'Rig 104'!$C:$C) -> 0 | AC7: =SUMIF('Rig 104'!$B:$B,Lists!$A$6,'Rig 104'!$E:$E) -> 0 | AD7: =SUMIF('Rig 104'!$B:$B,Lists!$A$6,'Rig 104'!$F:$F) -> 0 | AE7: =SUMIF('Rig 104'!$B:$B,Lists!$A$6,'Rig 104'!$G:$G) -> 0 | AF7: =SUMIF('Rig 104'!$B:$B,Lists!$A$6,'Rig 104'!$H:$H) -> 0 | AG7: =SUMIF('Rig 104'!$B:$B,Lists!$A$6,'Rig 104'!$I:$I) -> 0 | AH7: =SUMIF('Rig 104'!$B:$B,Lists!$A$7,'Rig 104'!$C:$C) -> 0 | AI7: =SUMIF('Rig 104'!$B:$B,Lists!$A$7,'Rig 104'!$E:$E) -> 0 | AJ7: =SUMIF('Rig 104'!$B:$B,Lists!$A$7,'Rig 104'!$F:$F) -> 0 | AK7: =SUMIF('Rig 104'!$B:$B,Lists!$A$7,'Rig 104'!$G:$G) -> 0 | AL7: =SUMIF('Rig 104'!$B:$B,Lists!$A$7,'Rig 104'!$H:$H) -> 0 | AM7: =SUMIF('Rig 104'!$B:$B,Lists!$A$7,'Rig 104'!$I:$I) -> 0 | AN7: =SUMIF('Rig 104'!$B:$B,Lists!$A$8,'Rig 104'!$C:$C) -> 0 | AO7: =SUMIF('Rig 104'!$B:$B,Lists!$A$8,'Rig 104'!$E:$E) -> 0 | AP7: =SUMIF('Rig 104'!$B:$B,Lists!$A$8,'Rig 104'!$F:$F) -> 0 | AQ7: =SUMIF('Rig 104'!$B:$B,Lists!$A$8,'Rig 104'!$G:$G) -> 0 | AR7: =SUMIF('Rig 104'!$B:$B,Lists!$A$8,'Rig 104'!$H:$H) -> 0 | AS7: =SUMIF('Rig 104'!$B:$B,Lists!$A$8,'Rig 104'!$I:$I) -> 0 | AT7: =SUMIF('Rig 104'!$B:$B,Lists!$A$9,'Rig 104'!$C:$C) -> 0 | AU7: =SUMIF('Rig 104'!$B:$B,Lists!$A$9,'Rig 104'!$E:$E) -> 0 | AV7: =SUMIF('Rig 104'!$B:$B,Lists!$A$9,'Rig 104'!$F:$F) -> 0 | AW7: =SUMIF('Rig 104'!$B:$B,Lists!$A$9,'Rig 104'!$G:$G) -> 0 | AX7: =SUMIF('Rig 104'!$B:$B,Lists!$A$9,'Rig 104'!$H:$H) -> 0 | AY7: =SUMIF('Rig 104'!$B:$B,Lists!$A$9,'Rig 104'!$I:$I) -> 0 | AZ7: =SUMIF('Rig 104'!$B:$B,Lists!$A$10,'Rig 104'!$C:$C) -> 0 | BA7: =SUMIF('Rig 104'!$B:$B,Lists!$A$10,'Rig 104'!$E:$E) -> 0 | BB7: =SUMIF('Rig 104'!$B:$B,Lists!$A$10,'Rig 104'!$F:$F) -> 0 | BC7: =SUMIF('Rig 104'!$B:$B,Lists!$A$10,'Rig 104'!$G:$G) -> 0 | BD7: =SUMIF('Rig 104'!$B:$B,Lists!$A$10,'Rig 104'!$H:$H) -> 0 | BE7: =SUMIF('Rig 104'!$B:$B,Lists!$A$10,'Rig 104'!$I:$I) -> 0 | BF7: =SUMIF('Rig 104'!$B:$B,Lists!$A$11,'Rig 104'!$C:$C) -> 324 | BG7: =SUMIF('Rig 104'!$B:$B,Lists!$A$11,'Rig 104'!$E:$E) -> 0 | BH7: =SUMIF('Rig 104'!$B:$B,Lists!$A$11,'Rig 104'!$F:$F) -> 0 | BI7: =SUMIF('Rig 104'!$B:$B,Lists!$A$11,'Rig 104'!$G:$G) -> 0 | BJ7: =SUMIF('Rig 104'!$B:$B,Lists!$A$11,'Rig 104'!$H:$H) -> 0 | BK7: =SUMIF('Rig 104'!$B:$B,Lists!$A$11,'Rig 104'!$I:$I) -> 0 | BL7: =SUMIF('Rig 104'!$B:$B,Lists!$A$12,'Rig 104'!$C:$C) -> 0 | BM7: =SUMIF('Rig 104'!$B:$B,Lists!$A$12,'Rig 104'!$E:$E) -> 0 | BN7: =SUMIF('Rig 104'!$B:$B,Lists!$A$12,'Rig 104'!$F:$F) -> 0 | BO7: =SUMIF('Rig 104'!$B:$B,Lists!$A$12,'Rig 104'!$G:$G) -> 0 | BP7: =SUMIF('Rig 104'!$B:$B,Lists!$A$12,'Rig 104'!$H:$H) -> 0 | BQ7: =SUMIF('Rig 104'!$B:$B,Lists!$A$12,'Rig 104'!$I:$I) -> 0 | BR7: =SUMIF('Rig 104'!$B:$B,Lists!$A$13,'Rig 104'!$C:$C) -> 0 | BS7: =SUMIF('Rig 104'!$B:$B,Lists!$A$13,'Rig 104'!$E:$E) -> 0 | BT7: =SUMIF('Rig 104'!$B:$B,Lists!$A$13,'Rig 104'!$F:$F) -> 0 | BU7: =SUMIF('Rig 104'!$B:$B,Lists!$A$13,'Rig 104'!$G:$G) -> 0 | BV7: =SUMIF('Rig 104'!$B:$B,Lists!$A$13,'Rig 104'!$H:$H) -> 0 | BW7: =SUMIF('Rig 104'!$B:$B,Lists!$A$13,'Rig 104'!$I:$I) -> 0 | BX7: =SUMIF('Rig 104'!$B:$B,Lists!$A$14,'Rig 104'!$C:$C) -> 0 | BY7: =SUMIF('Rig 104'!$B:$B,Lists!$A$14,'Rig 104'!$E:$E) -> 0 | BZ7: =SUMIF('Rig 104'!$B:$B,Lists!$A$14,'Rig 104'!$F:$F) -> 0 | CA7: =SUMIF('Rig 104'!$B:$B,Lists!$A$14,'Rig 104'!$G:$G) -> 0 | CB7: =SUMIF('Rig 104'!$B:$B,Lists!$A$14,'Rig 104'!$H:$H) -> 0 | CC7: =SUMIF('Rig 104'!$B:$B,Lists!$A$14,'Rig 104'!$I:$I) -> 0 | CD7: =SUMIF('Rig 104'!$B:$B,Lists!$A$15,'Rig 104'!$C:$C) -> 0 | CE7: =SUMIF('Rig 104'!$B:$B,Lists!$A$15,'Rig 104'!$E:$E) -> 0 | CF7: =SUMIF('Rig 104'!$B:$B,Lists!$A$15,'Rig 104'!$F:$F) -> 0 | CG7: =SUMIF('Rig 104'!$B:$B,Lists!$A$15,'Rig 104'!$G:$G) -> 0 | CH7: =SUMIF('Rig 104'!$B:$B,Lists!$A$15,'Rig 104'!$H:$H) -> 0 | CI7: =SUMIF('Rig 104'!$B:$B,Lists!$A$15,'Rig 104'!$I:$I) -> 0 | CJ7: =SUMIF('Rig 104'!$B:$B,Lists!$A$16,'Rig 104'!$C:$C) -> 0 | CK7: =SUMIF('Rig 104'!$B:$B,Lists!$A$16,'Rig 104'!$E:$E) -> 0 | CL7: =SUMIF('Rig 104'!$B:$B,Lists!$A$16,'Rig 104'!$F:$F) -> 0 | CM7: =SUMIF('Rig 104'!$B:$B,Lists!$A$16,'Rig 104'!$G:$G) -> 0 | CN7: =SUMIF('Rig 104'!$B:$B,Lists!$A$16,'Rig 104'!$H:$H) -> 0 | CO7: =SUMIF('Rig 104'!$B:$B,Lists!$A$16,'Rig 104'!$I:$I) -> 0 | CP7: =SUMIF('Rig 104'!$B:$B,Lists!$A$17,'Rig 104'!$C:$C) -> 0 | CQ7: =SUMIF('Rig 104'!$B:$B,Lists!$A$17,'Rig 104'!$E:$E) -> 0 | CR7: =SUMIF('Rig 104'!$B:$B,Lists!$A$17,'Rig 104'!$F:$F) -> 0 | CS7: =SUMIF('Rig 104'!$B:$B,Lists!$A$17,'Rig 104'!$G:$G) -> 0 | CT7: =SUMIF('Rig 104'!$B:$B,Lists!$A$17,'Rig 104'!$H:$H) -> 0 | CU7: =SUMIF('Rig 104'!$B:$B,Lists!$A$17,'Rig 104'!$I:$I) -> 0 | CV7: =SUMIF('Rig 104'!$B:$B,Lists!$A$18,'Rig 104'!$C:$C) -> 43 | CW7: =SUMIF('Rig 104'!$B:$B,Lists!$A$18,'Rig 104'!$E:$E) -> 0 | CX7: =SUMIF('Rig 104'!$B:$B,Lists!$A$18,'Rig 104'!$F:$F) -> 0 | CY7: =SUMIF('Rig 104'!$B:$B,Lists!$A$18,'Rig 104'!$G:$G) -> 0 | CZ7: =SUMIF('Rig 104'!$B:$B,Lists!$A$18,'Rig 104'!$H:$H) -> 0 | DA7: =SUMIF('Rig 104'!$B:$B,Lists!$A$18,'Rig 104'!$I:$I) -> 0 | DB7: =SUMIF('Rig 104'!$B:$B,Lists!$A$19,'Rig 104'!$C:$C) -> 43 | DC7: =SUMIF('Rig 104'!$B:$B,Lists!$A$19,'Rig 104'!$E:$E) -> 0 | DD7: =SUMIF('Rig 104'!$B:$B,Lists!$A$19,'Rig 104'!$F:$F) -> 0 | DE7: =SUMIF('Rig 104'!$B:$B,Lists!$A$19,'Rig 104'!$G:$G) -> 0 | DF7: =SUMIF('Rig 104'!$B:$B,Lists!$A$19,'Rig 104'!$H:$H) -> 0 | DG7: =SUMIF('Rig 104'!$B:$B,Lists!$A$19,'Rig 104'!$I:$I) -> 0 | DH7: =SUMIF('Rig 104'!$B:$B,Lists!$A$20,'Rig 104'!$C:$C) -> 0 | DI7: =SUMIF('Rig 104'!$B:$B,Lists!$A$20,'Rig 104'!$E:$E) -> 0 | DJ7: =SUMIF('Rig 104'!$B:$B,Lists!$A$20,'Rig 104'!$F:$F) -> 0 | DK7: =SUMIF('Rig 104'!$B:$B,Lists!$A$20,'Rig 104'!$G:$G) -> 0 | DL7: =SUMIF('Rig 104'!$B:$B,Lists!$A$20,'Rig 104'!$H:$H) -> 0 | DM7: =SUMIF('Rig 104'!$B:$B,Lists!$A$20,'Rig 104'!$I:$I) -> 0 | DN7: =SUMIF('Rig 104'!$B:$B,Lists!$A$21,'Rig 104'!$C:$C) -> 0 | DO7: =SUMIF('Rig 104'!$B:$B,Lists!$A$21,'Rig 104'!$E:$E) -> 0 | DP7: =SUMIF('Rig 104'!$B:$B,Lists!$A$21,'Rig 104'!$F:$F) -> 0 | DQ7: =SUMIF('Rig 104'!$B:$B,Lists!$A$21,'Rig 104'!$G:$G) -> 0 | DR7: =SUMIF('Rig 104'!$B:$B,Lists!$A$21,'Rig 104'!$H:$H) -> 0 | DS7: =SUMIF('Rig 104'!$B:$B,Lists!$A$21,'Rig 104'!$I:$I) -> 0 | DT7: =SUMIF('Rig 104'!$B:$B,Lists!$A$22,'Rig 104'!$C:$C) -> 0 | DU7: =SUMIF('Rig 104'!$B:$B,Lists!$A$22,'Rig 104'!$E:$E) -> 0 | DV7: =SUMIF('Rig 104'!$B:$B,Lists!$A$22,'Rig 104'!$F:$F) -> 0 | DW7: =SUMIF('Rig 104'!$B:$B,Lists!$A$22,'Rig 104'!$G:$G) -> 0 | DX7: =SUMIF('Rig 104'!$B:$B,Lists!$A$22,'Rig 104'!$H:$H) -> 0 | DY7: =SUMIF('Rig 104'!$B:$B,Lists!$A$22,'Rig 104'!$I:$I) -> 0 | DZ7: =SUMIF('Rig 104'!$B:$B,Lists!$A$23,'Rig 104'!$C:$C) -> 0 | EA7: =SUMIF('Rig 104'!$B:$B,Lists!$A$23,'Rig 104'!$E:$E) -> 0 | EB7: =SUMIF('Rig 104'!$B:$B,Lists!$A$23,'Rig 104'!$F:$F) -> 0 | EC7: =SUMIF('Rig 104'!$B:$B,Lists!$A$23,'Rig 104'!$G:$G) -> 0 | ED7: =SUMIF('Rig 104'!$B:$B,Lists!$A$23,'Rig 104'!$H:$H) -> 0 | EE7: =SUMIF('Rig 104'!$B:$B,Lists!$A$23,'Rig 104'!$I:$I) -> 0 | EF7: =SUMIF('Rig 104'!$B:$B,Lists!$A$24,'Rig 104'!$C:$C) -> 30 | EG7: =SUMIF('Rig 104'!$B:$B,Lists!$A$24,'Rig 104'!$E:$E) -> 0 | EH7: =SUMIF('Rig 104'!$B:$B,Lists!$A$24,'Rig 104'!$F:$F) -> 0 | EI7: =SUMIF('Rig 104'!$B:$B,Lists!$A$24,'Rig 104'!$G:$G) -> 0 | EJ7: =SUMIF('Rig 104'!$B:$B,Lists!$A$24,'Rig 104'!$H:$H) -> 0 | EK7: =SUMIF('Rig 104'!$B:$B,Lists!$A$24,'Rig 104'!$I:$I) -> 0 | EL7: =SUMIF('Rig 104'!$B:$B,Lists!$A$25,'Rig 104'!$C:$C) -> 30 | EM7: =SUMIF('Rig 104'!$B:$B,Lists!$A$25,'Rig 104'!$E:$E) -> 0 | EN7: =SUMIF('Rig 104'!$B:$B,Lists!$A$25,'Rig 104'!$F:$F) -> 0 | EO7: =SUMIF('Rig 104'!$B:$B,Lists!$A$25,'Rig 104'!$G:$G) -> 0 | EP7: =SUMIF('Rig 104'!$B:$B,Lists!$A$25,'Rig 104'!$H:$H) -> 0 | EQ7: =SUMIF('Rig 104'!$B:$B,Lists!$A$25,'Rig 104'!$I:$I) -> 0 | ER7: =SUMIF('Rig 104'!$B:$B,Lists!$A$26,'Rig 104'!$C:$C) -> 0 | ES7: =SUMIF('Rig 104'!$B:$B,Lists!$A$26,'Rig 104'!$E:$E) -> 0 | ET7: =SUMIF('Rig 104'!$B:$B,Lists!$A$26,'Rig 104'!$F:$F) -> 0 | EU7: =SUMIF('Rig 104'!$B:$B,Lists!$A$26,'Rig 104'!$G:$G) -> 0 | EV7: =SUMIF('Rig 104'!$B:$B,Lists!$A$26,'Rig 104'!$H:$H) -> 0 | EW7: =SUMIF('Rig 104'!$B:$B,Lists!$A$26,'Rig 104'!$I:$I) -> 0 | EX7: =SUMIF('Rig 104'!$B:$B,Lists!$A$27,'Rig 104'!$C:$C) -> 0 | EY7: =SUMIF('Rig 104'!$B:$B,Lists!$A$27,'Rig 104'!$E:$E) -> 0 | EZ7: =SUMIF('Rig 104'!$B:$B,Lists!$A$27,'Rig 104'!$F:$F) -> 0 | FA7: =SUMIF('Rig 104'!$B:$B,Lists!$A$27,'Rig 104'!$G:$G) -> 0 | FB7: =SUMIF('Rig 104'!$B:$B,Lists!$A$27,'Rig 104'!$H:$H) -> 0 | FC7: =SUMIF('Rig 104'!$B:$B,Lists!$A$27,'Rig 104'!$I:$I) -> 0 | FD7: =SUMIF('Rig 104'!$B:$B,Lists!$A$28,'Rig 104'!$C:$C) -> 0 | FE7: =SUMIF('Rig 104'!$B:$B,Lists!$A$28,'Rig 104'!$E:$E) -> 0 | FF7: =SUMIF('Rig 104'!$B:$B,Lists!$A$28,'Rig 104'!$F:$F) -> 0 | FG7: =SUMIF('Rig 104'!$B:$B,Lists!$A$28,'Rig 104'!$G:$G) -> 0 | FH7: =SUMIF('Rig 104'!$B:$B,Lists!$A$28,'Rig 104'!$H:$H) -> 0 | FI7: =SUMIF('Rig 104'!$B:$B,Lists!$A$28,'Rig 104'!$I:$I) -> 0 | FJ7: =SUMIF('Rig 104'!$B:$B,Lists!$A$29,'Rig 104'!$C:$C) -> 20 | FK7: =SUMIF('Rig 104'!$B:$B,Lists!$A$29,'Rig 104'!$E:$E) -> 0 | FL7: =SUMIF('Rig 104'!$B:$B,Lists!$A$29,'Rig 104'!$F:$F) -> 0 | FM7: =SUMIF('Rig 104'!$B:$B,Lists!$A$29,'Rig 104'!$G:$G) -> 0 | FN7: =SUMIF('Rig 104'!$B:$B,Lists!$A$29,'Rig 104'!$H:$H) -> 0 | FO7: =SUMIF('Rig 104'!$B:$B,Lists!$A$29,'Rig 104'!$I:$I) -> 0 | FP7: =SUMIF('Rig 104'!$B:$B,Lists!$A$30,'Rig 104'!$C:$C) -> 0 | FQ7: =SUMIF('Rig 104'!$B:$B,Lists!$A$30,'Rig 104'!$E:$E) -> 0 | FR7: =SUMIF('Rig 104'!$B:$B,Lists!$A$30,'Rig 104'!$F:$F) -> 0 | FS7: =SUMIF('Rig 104'!$B:$B,Lists!$A$30,'Rig 104'!$G:$G) -> 0 | FT7: =SUMIF('Rig 104'!$B:$B,Lists!$A$30,'Rig 104'!$H:$H) -> 0 | FU7: =SUMIF('Rig 104'!$B:$B,Lists!$A$30,'Rig 104'!$I:$I) -> 0 | FV7: =SUMIF('Rig 104'!$B:$B,Lists!$A$31,'Rig 104'!$C:$C) -> 0 | FW7: =SUMIF('Rig 104'!$B:$B,Lists!$A$31,'Rig 104'!$E:$E) -> 0 | FX7: =SUMIF('Rig 104'!$B:$B,Lists!$A$31,'Rig 104'!$F:$F) -> 0 | FY7: =SUMIF('Rig 104'!$B:$B,Lists!$A$31,'Rig 104'!$G:$G) -> 0 | FZ7: =SUMIF('Rig 104'!$B:$B,Lists!$A$31,'Rig 104'!$H:$H) -> 0 | GA7: =SUMIF('Rig 104'!$B:$B,Lists!$A$31,'Rig 104'!$I:$I) -> 0 | GB7: =SUMIF('Rig 104'!$B:$B,Lists!$A$32,'Rig 104'!$C:$C) -> 0 | GC7: =SUMIF('Rig 104'!$B:$B,Lists!$A$32,'Rig 104'!$E:$E) -> 0 | GD7: =SUMIF('Rig 104'!$B:$B,Lists!$A$32,'Rig 104'!$F:$F) -> 0 | GE7: =SUMIF('Rig 104'!$B:$B,Lists!$A$32,'Rig 104'!$G:$G) -> 0 | GF7: =SUMIF('Rig 104'!$B:$B,Lists!$A$32,'Rig 104'!$H:$H) -> 0 | GG7: =SUMIF('Rig 104'!$B:$B,Lists!$A$32,'Rig 104'!$I:$I) -> 0 | GH7: =SUMIF('Rig 104'!$B:$B,Lists!$A$33,'Rig 104'!$C:$C) -> 0 | GI7: =SUMIF('Rig 104'!$B:$B,Lists!$A$33,'Rig 104'!$E:$E) -> 0 | GJ7: =SUMIF('Rig 104'!$B:$B,Lists!$A$33,'Rig 104'!$F:$F) -> 0 | GK7: =SUMIF('Rig 104'!$B:$B,Lists!$A$33,'Rig 104'!$G:$G) -> 0 | GL7: =SUMIF('Rig 104'!$B:$B,Lists!$A$33,'Rig 104'!$H:$H) -> 0 | GM7: =SUMIF('Rig 104'!$B:$B,Lists!$A$33,'Rig 104'!$I:$I) -> 0 | GN7: =SUMIF('Rig 104'!$B:$B,Lists!$A$34,'Rig 104'!$C:$C) -> 0 | GO7: =SUMIF('Rig 104'!$B:$B,Lists!$A$34,'Rig 104'!$E:$E) -> 0 | GP7: =SUMIF('Rig 104'!$B:$B,Lists!$A$34,'Rig 104'!$F:$F) -> 0 | GQ7: =SUMIF('Rig 104'!$B:$B,Lists!$A$34,'Rig 104'!$G:$G) -> 0 | GR7: =SUMIF('Rig 104'!$B:$B,Lists!$A$34,'Rig 104'!$H:$H) -> 0 | GS7: =SUMIF('Rig 104'!$B:$B,Lists!$A$34,'Rig 104'!$I:$I) -> 0 | GT7: =SUMIF('Rig 104'!$B:$B,Lists!$A$35,'Rig 104'!$C:$C) -> 0 | GU7: =SUMIF('Rig 104'!$B:$B,Lists!$A$35,'Rig 104'!$E:$E) -> 0 | GV7: =SUMIF('Rig 104'!$B:$B,Lists!$A$35,'Rig 104'!$F:$F) -> 0 | GW7: =SUMIF('Rig 104'!$B:$B,Lists!$A$35,'Rig 104'!$G:$G) -> 0 | GX7: =SUMIF('Rig 104'!$B:$B,Lists!$A$35,'Rig 104'!$H:$H) -> 0 | GY7: =SUMIF('Rig 104'!$B:$B,Lists!$A$35,'Rig 104'!$I:$I) -> 0 | GZ7: =SUMIF('Rig 104'!$B:$B,Lists!$A$36,'Rig 104'!$C:$C) -> 0 | HA7: =SUMIF('Rig 104'!$B:$B,Lists!$A$36,'Rig 104'!$E:$E) -> 0 | HB7: =SUMIF('Rig 104'!$B:$B,Lists!$A$36,'Rig 104'!$F:$F) -> 0 | HC7: =SUMIF('Rig 104'!$B:$B,Lists!$A$36,'Rig 104'!$G:$G) -> 0 | HD7: =SUMIF('Rig 104'!$B:$B,Lists!$A$36,'Rig 104'!$H:$H) -> 0 | HE7: =SUMIF('Rig 104'!$B:$B,Lists!$A$36,'Rig 104'!$I:$I) -> 0 | HF7: =SUMIF('Rig 104'!$B:$B,Lists!$A$37,'Rig 104'!$C:$C) -> 0 | HG7: =SUMIF('Rig 104'!$B:$B,Lists!$A$37,'Rig 104'!$E:$E) -> 0 | HH7: =SUMIF('Rig 104'!$B:$B,Lists!$A$37,'Rig 104'!$F:$F) -> 0 | HI7: =SUMIF('Rig 104'!$B:$B,Lists!$A$37,'Rig 104'!$G:$G) -> 0 | HJ7: =SUMIF('Rig 104'!$B:$B,Lists!$A$37,'Rig 104'!$H:$H) -> 0 | HK7: =SUMIF('Rig 104'!$B:$B,Lists!$A$37,'Rig 104'!$I:$I) -> 0 | HL7: =SUMIF('Rig 104'!$B:$B,Lists!$A$38,'Rig 104'!$C:$C) -> 0 | HM7: =SUMIF('Rig 104'!$B:$B,Lists!$A$38,'Rig 104'!$E:$E) -> 0 | HN7: =SUMIF('Rig 104'!$B:$B,Lists!$A$38,'Rig 104'!$F:$F) -> 0 | HO7: =SUMIF('Rig 104'!$B:$B,Lists!$A$38,'Rig 104'!$G:$G) -> 0 | HP7: =SUMIF('Rig 104'!$B:$B,Lists!$A$38,'Rig 104'!$H:$H) -> 0 | HQ7: =SUMIF('Rig 104'!$B:$B,Lists!$A$38,'Rig 104'!$I:$I) -> 0 | HR7: =SUMIF('Rig 104'!$B:$B,Lists!$A$39,'Rig 104'!$C:$C) -> 6 | HS7: =SUMIF('Rig 104'!$B:$B,Lists!$A$39,'Rig 104'!$E:$E) -> 0 | HT7: =SUMIF('Rig 104'!$B:$B,Lists!$A$39,'Rig 104'!$F:$F) -> 0 | HU7: =SUMIF('Rig 104'!$B:$B,Lists!$A$39,'Rig 104'!$G:$G) -> 0 | HV7: =SUMIF('Rig 104'!$B:$B,Lists!$A$39,'Rig 104'!$H:$H) -> 0 | HW7: =SUMIF('Rig 104'!$B:$B,Lists!$A$39,'Rig 104'!$I:$I) -> 0 | HX7: =SUMIF('Rig 104'!$B:$B,Lists!$A$40,'Rig 104'!$C:$C) -> 0 | HY7: =SUMIF('Rig 104'!$B:$B,Lists!$A$40,'Rig 104'!$E:$E) -> 0 | HZ7: =SUMIF('Rig 104'!$B:$B,Lists!$A$40,'Rig 104'!$F:$F) -> 0 | IA7: =SUMIF('Rig 104'!$B:$B,Lists!$A$40,'Rig 104'!$G:$G) -> 0 | IB7: =SUMIF('Rig 104'!$B:$B,Lists!$A$40,'Rig 104'!$H:$H) -> 0 | IC7: =SUMIF('Rig 104'!$B:$B,Lists!$A$40,'Rig 104'!$I:$I) -> 0 | ID7: =SUMIF('Rig 104'!$B:$B,Lists!$A$41,'Rig 104'!$C:$C) -> 0 | IE7: =SUMIF('Rig 104'!$B:$B,Lists!$A$41,'Rig 104'!$E:$E) -> 0 | IF7: =SUMIF('Rig 104'!$B:$B,Lists!$A$41,'Rig 104'!$F:$F) -> 0 | IG7: =SUMIF('Rig 104'!$B:$B,Lists!$A$41,'Rig 104'!$G:$G) -> 0 | IH7: =SUMIF('Rig 104'!$B:$B,Lists!$A$41,'Rig 104'!$H:$H) -> 0 | II7: =SUMIF('Rig 104'!$B:$B,Lists!$A$41,'Rig 104'!$I:$I) -> 0
